<?xml version="1.0" ?>
<robot name="marm">

  <material name="DarkGrey">
    <color rgba="0.3 0.3 0.3 1.0"/>
  </material>

<!-- /    COLOR    / -->
	<material name="Black">
		<color rgba="0 0 0 1"/>
	</material>
	<material name="White">
		<color rgba="1 1 1 1"/>
	</material>
	<material name="Blue">
		<color rgba="0 0 1 1"/>
	</material>
	<material name="Red">
		<color rgba="1 0 0 1"/>
	</material>

  <link name="world" />
  <joint name="world_base" type="fixed">
    <origin
      xyz="0 0 0"
      rpy="0 0 0" />
    <parent
      link="world" />
    <child
      link="base_link" />
  </joint>

<!-- /    BASE    / -->
	<link name="base_link">
	<inertial>
      <mass value="2.0"/>
      <origin xyz="0 0 0.1"/>
      <inertia ixx="0.00381666666667" ixy="0" ixz="0" iyy="0.0036" iyz="0" izz="0.00381666666667"/>
    </inertial>
		<visual>
			<origin rpy="0 0 0" xyz="0 0 0.1"/>
			<geometry>
				<cylinder length="0.2" radius="0.05"/>
			</geometry>
			<material name="White"/>
		</visual>
	</link>

	<!-- /   LINK1  // -->
	 <link name="link1">
		<inertial>
		<mass value="2.0"/>
		<origin rpy="0 0 0" xyz="0 0 -0.071302435"/>
		<inertia ixx="0.01" ixy="0" ixz="0" iyy="0.01" iyz="0" izz="0.02"/>
		</inertial>
		<visual>
			<origin rpy="0 0  0" xyz="0 0 -0.071302435"/>
			<geometry>
				<cylinder length="0.14260487" radius="0.03"/>
			</geometry>
			<material name="Blue"/>
		</visual>
	</link>

	<joint name="joint1" type="revolute">
		<parent link="base_link"/>
		<child link="link1"/>
		<origin rpy="0 0 0" xyz="0 0 0.34260487"/>
		<axis xyz=" 0 0 1"/>
		<limit effort="300" lower="-3.14159" upper="3.14159" velocity="1"/>
	</joint> 

    <transmission name="trans_joint1">
        <type>transmission_interface/SimpleTransmission</type>
        <joint name="joint1">
            <hardwareInterface>hardware_interface/EffortJointInterface</hardwareInterface>
        </joint>
        <actuator name="joint1_motor">
            <hardwareInterface>hardware_interface/EffortJointInterface</hardwareInterface>
            <mechanicalReduction>1</mechanicalReduction>
        </actuator>
    </transmission>
 
    <gazebo>
        <plugin name="gazebo_ros_control" filename="libgazebo_ros_control.so">
            <!-- <robotNamespace>/tmi_pro5</robotNamespace> -->
            <robotNamespace>/</robotNamespace>
            <controlPeriod>0.001</controlPeriod>
            <legacyModeNS>false</legacyModeNS>
        </plugin>
    </gazebo>

</robot>


