<?xml version="1.0" ?>
<robot name="marm">

  <material name="DarkGrey">
    <color rgba="0.3 0.3 0.3 1.0"/>
  </material>

<!-- /    COLOR    / -->
	<material name="Black">
		<color rgba="0 0 0 1"/>
	</material>
	<material name="White">
		<color rgba="1 1 1 1"/>
	</material>
	<material name="Blue">
		<color rgba="0 0 1 1"/>
	</material>
	<material name="Red">
		<color rgba="1 0 0 1"/>
	</material>

  <link name="world" />
  <joint name="world_base" type="fixed">
    <origin
      xyz="0 0 0"
      rpy="0 0 0" />
    <parent
      link="world" />
    <child
      link="base_link" />
  </joint>

<!-- /    BASE    / -->
	<link name="base_link">
	<inertial>
      <mass value="2.0"/>
      <origin xyz="0 0 0.1"/>
      <inertia ixx="0.00381666666667" ixy="0" ixz="0" iyy="0.0036" iyz="0" izz="0.00381666666667"/>
    </inertial>
		<visual>
			<origin rpy="0 0 0" xyz="0 0 0.1"/>
			<geometry>
				<cylinder length="0.2" radius="0.05"/>
			</geometry>
			<material name="White"/>
		</visual>
	</link>

	<!-- /   LINK1  // -->
	 <link name="link1">
		<inertial>
		<mass value="2.0"/>
		<origin rpy="0 0 0" xyz="0 0 -0.071302435"/>
		<inertia ixx="0.01" ixy="0" ixz="0" iyy="0.01" iyz="0" izz="0.2"/>
		</inertial>
		<visual>
			<origin rpy="0 0  0" xyz="0 0 -0.071302435"/>
			<geometry>
				<cylinder length="0.14260487" radius="0.03"/>
			</geometry>
			<material name="Blue"/>
		</visual>
	</link>

	<joint name="joint1" type="revolute">
		<parent link="base_link"/>
		<child link="link1"/>
		<origin rpy="0 0 0" xyz="0 0 0.34260487"/>
		<axis xyz=" 0 0 1"/>
		<limit effort="300" lower="-3.14159" upper="3.14159" velocity="1"/>
	</joint> 

	<!-- /   LINK2  // -->

	 <link name="link2">
		<inertial>
		<mass value="3.0"/>
		<origin rpy="0 0 0" xyz="0 -0.15 0.09"/>
		<inertia ixx="0.01" ixy="0" ixz="0" iyy="0.01" iyz="0" izz="0.2"/>
		</inertial>
		<visual>
			<origin rpy="0  0  0" xyz="0 0 0.05"/>
			<geometry>
				<cylinder length="0.1" radius="0.02"/>
			</geometry>
			<material name="White"/>
		</visual>
		<visual>
			<origin rpy="1.5707963  0  0" xyz="0 -0.196469 0.1"/>
			<geometry>
				<cylinder length="0.392938" radius="0.04"/>
			</geometry>
			<material name="White"/>
		</visual>
	</link>

	<joint name="joint2" type="revolute">
		<parent link="link1"/>
		<child link="link2"/>
		<origin rpy="-1.5707963 0 0" xyz="0 0 0"/>
		<axis xyz=" 0 0 1"/>
		<limit effort="300" lower="-3.14159" upper="3.14159" velocity="1"/>
	</joint> 

	<!-- /   LINK3  // -->

	 <link name="link3">
		<inertial>
		<mass value="3.0"/>
		<origin rpy="0 0 0" xyz="0 0 -0.182786005"/>
		<inertia ixx="0.01" ixy="0" ixz="0" iyy="0.01" iyz="0" izz="0.2"/>
		</inertial>
		<visual>
			<origin rpy="1.5707963 0  0" xyz="0 0.02  -0.36557201"/>
			<geometry>
				<cylinder length="0.04" radius="0.04"/>
			</geometry>
			<material name="Blue"/>
		</visual>
		 <visual>
			<origin rpy="0 0  0" xyz="0 0 -0.182786005"/>
			<geometry>
				<cylinder length="0.36557201" radius="0.03"/>
			</geometry>
			<material name="Blue"/>
		</visual>
	</link>


	<joint name="joint3" type="revolute">
		<parent link="link2"/>
		<child link="link3"/>
		<origin rpy="1.5707963 0 0" xyz="0 -0.7851 0"/>
		<axis xyz=" 0 0 1"/>
		<limit effort="300" lower="-3.14159" upper="3.14159" velocity="1"/>
	</joint> 

	<!-- /   LINK4  // -->

	 <link name="link4">
		<inertial>
		<mass value="2.5"/>
		<origin rpy="0 0 0" xyz="0 -0.196469 0.08"/>
		<inertia ixx="0.05" ixy="0" ixz="0" iyy="0.03" iyz="0" izz="0.3"/>
		</inertial>
		<visual>
			<origin rpy="0  0  0" xyz="0 0  0.05"/>
			<geometry>
				<cylinder length="0.1" radius="0.02"/>
			</geometry>
			<material name="White"/>
		</visual>
		<visual>
			<origin rpy="1.5707963  0  0" xyz="0 -0.196469 0.1"/>
			<geometry>
				<cylinder length="0.392938" radius="0.04"/>
			</geometry>
			<material name="White"/>
		</visual>

	</link>

	<joint name="joint4" type="revolute">
		<parent link="link3"/>
		<child link="link4"/>
		<origin rpy="-1.5707963 0 0" xyz="0 0 0"/>  
		<!-- </0.36557201/> -->
		<axis xyz=" 0 0 1"/>
		<limit effort="300" lower="-3.14159" upper="3.14159" velocity="1"/>
	</joint> 

    <transmission name="trans_joint1">
        <type>transmission_interface/SimpleTransmission</type>
        <joint name="joint1">
            <hardwareInterface>hardware_interface/EffortJointInterface</hardwareInterface>
        </joint>
        <actuator name="joint1_motor">
            <hardwareInterface>hardware_interface/EffortJointInterface</hardwareInterface>
            <mechanicalReduction>1</mechanicalReduction>
        </actuator>
    </transmission>
 
     <transmission name="trans_joint2">
        <type>transmission_interface/SimpleTransmission</type>
        <joint name="joint2">
            <hardwareInterface>hardware_interface/EffortJointInterface</hardwareInterface>
        </joint>
        <actuator name="joint2_motor">
            <hardwareInterface>hardware_interface/EffortJointInterface</hardwareInterface>
            <mechanicalReduction>1</mechanicalReduction>
        </actuator>
    </transmission>
	<transmission name="trans_joint3">
	<type>transmission_interface/SimpleTransmission</type>
	<joint name="joint3">
		<hardwareInterface>hardware_interface/EffortJointInterface</hardwareInterface>
	</joint>
	<actuator name="joint3_motor">
		<hardwareInterface>hardware_interface/EffortJointInterface</hardwareInterface>
		<mechanicalReduction>1</mechanicalReduction>
	</actuator>
	</transmission>
		<transmission name="trans_joint4">
		<type>transmission_interface/SimpleTransmission</type>
		<joint name="joint4">
			<hardwareInterface>hardware_interface/EffortJointInterface</hardwareInterface>
		</joint>
		<actuator name="joint4_motor">
			<hardwareInterface>hardware_interface/EffortJointInterface</hardwareInterface>
			<mechanicalReduction>1</mechanicalReduction>
		</actuator>
	</transmission>
    <gazebo>
        <plugin name="gazebo_ros_control" filename="libgazebo_ros_control.so">
            <!-- <robotNamespace>/tmi_pro5</robotNamespace> -->
            <robotNamespace>/</robotNamespace>
            <controlPeriod>0.001</controlPeriod>
            <legacyModeNS>false</legacyModeNS>
        </plugin>
    </gazebo>

</robot>


